Workbook

Sheet Fiber Specification
A2: engionic Femto Gratings GmbH - Am Stollen 19B - 38640 Goslar | H2: V1.14
A4: Production Sheet Number: | E4: Postition: | F4: 2 | G4: of: | H4: 2
A5: Offer Number: | C5: 41260063 | E5: Customer: | F5: IFIC
A6: Customer Product ID: | E6: Quantity: | F6: 10
A8: Contact: | B8: Kampling | D8: Approved By: | G8: Date:
A10: Remarks: | B10: Fiber with additional 400µm PEEK coating after FBG inscription and FC/APC connector at lead in, tolerance lead in and lead out +/-5mm, tolerance fiber length +/-50mm
A12: Fiber Specification
A13: Fiber Type | B13: Fiber Core Type | C13: ITU-T | D13: Fiber Cladding Diameter (µm) | E13: Fiber Coating Material | F13: Fiber Manufacturer | H13: Fiber Provided By
A14: SM1330-E9/125PI | B14: =VLOOKUP($A$14,Definitions!C2:I16,2,0) -> Single Mode | C14: =VLOOKUP($A$14,Definitions!C2:I16,7,0) -> - | D14: =VLOOKUP($A$14,Definitions!C2:I16,4,0) -> 125 | E14: =VLOOKUP($A$14,Definitions!C2:I16,5,0) -> Polyimide | F14: =VLOOKUP($A$14,Definitions!C2:I16,6,0) -> J-Fiber | H14: eFG
A16: FBG Specification
B17: Wavelength (nm) | C17: Reflectivity (%) | D17: FWHM (nm) | E17: min SLSR (dB) | F17: FBG Length (mm) | G17: FemtoPlus | H17: Apodized
A18: Nominal Value | B18: - | C18: 25 | D18: 0.12 | E18: 20 | F18: 11 | G18: yes | H18: yes
A19: Plus Tolerance | B19: 0.2 | C19: 8 | D19: 0.03 | E19: - | F19: 1
A20: Minus Tolerance | B20: 0.2 | C20: 8 | D20: 0.03 | E20: - | F20: 1
A22: Fiber Design
A25: Additional Specifications
A26: Spectrum on Datasheet | B26: Label | C26: Total Fiber Length (mm) | D26: Simplified Packaging1 | E26: Tolerance FBG Spacing (%)2 | F26: FBG Marking | H26: Fiber Input Marking
A27: linear | B27: on spool | C27: 13686.5 | D27: yes | E27: 1 | F27: black, FBG-length (±1mm tolerance) | H27: black
A29: Wavelength Table
A30: FBG Name | B30: Wavelength (nm) | C30: FBG Position (mm) | D30: FBG Lead Out (mm) | E30: FBG Spacing (mm)
A31: =IF($G$33 > ROW()-ROW($A$31),CONCATENATE("FBG",ROW()-ROW($A$30)),"") -> FBG1 | B31: =G43 -> 1535 | C31: 244 | D31: =IF(ISNUMBER(C31),$C$27-$C31,"") -> 13442.5 | E31: - | G31: Auto Fill Wavelength Table
A32: =IF($G$33 > ROW()-ROW($A$31),CONCATENATE("FBG",ROW()-ROW($A$30)),"") -> FBG2 | B32: =IF(Definitions!$W$2,IF($G$33 > ROW()-ROW($A$31),$B31+$G$41,""),"") -> 1536.15 | C32: 562 | D32: =IF(ISNUMBER(C32),$C$27-$C32,"") -> 13124.5 | E32: =IF(ISNUMBER(C32),C32-C31,"") -> 318 | G32: Number of FBGs
A33: =IF($G$33 > ROW()-ROW($A$31),CONCATENATE("FBG",ROW()-ROW($A$30)),"") -> FBG3 | B33: =IF(Definitions!$W$2,IF($G$33 > ROW()-ROW($A$31),$B32+$G$41,""),"") -> 1537.3 | C33: =IF(AND($G$33 > ROW()-ROW($A$31),Definitions!$Y$2),$C32+$G$48,"") -> 1062 | D33: =IF(ISNUMBER(C33),$C$27-$C33,"") -> 12624.5 | E33: =IF(ISNUMBER(C33),C33-C32,"") -> 500 | G33: 28
A34: =IF($G$33 > ROW()-ROW($A$31),CONCATENATE("FBG",ROW()-ROW($A$30)),"") -> FBG4 | B34: =IF(Definitions!$W$2,IF($G$33 > ROW()-ROW($A$31),$B33+$G$41,""),"") -> 1538.45 | C34: =IF(AND($G$33 > ROW()-ROW($A$31),Definitions!$Y$2),$C33+$G$48,"") -> 1562 | D34: =IF(ISNUMBER(C34),$C$27-$C34,"") -> 12124.5 | E34: =IF(ISNUMBER(C34),C34-C33,"") -> 500
A35: =IF($G$33 > ROW()-ROW($A$31),CONCATENATE("FBG",ROW()-ROW($A$30)),"") -> FBG5 | B35: =IF(Definitions!$W$2,IF($G$33 > ROW()-ROW($A$31),$B34+$G$41,""),"") -> 1539.6 | C35: =IF(AND($G$33 > ROW()-ROW($A$31),Definitions!$Y$2),$C34+$G$48,"") -> 2062 | D35: =IF(ISNUMBER(C35),$C$27-$C35,"") -> 11624.5 | E35: =IF(ISNUMBER(C35),C35-C34,"") -> 500 | G35: Position First FBG (mm)
A36: =IF($G$33 > ROW()-ROW($A$31),CONCATENATE("FBG",ROW()-ROW($A$30)),"") -> FBG6 | B36: =IF(Definitions!$W$2,IF($G$33 > ROW()-ROW($A$31),$B35+$G$41,""),"") -> 1540.75 | C36: =IF(AND($G$33 > ROW()-ROW($A$31),Definitions!$Y$2),$C35+$G$48,"") -> 2562 | D36: =IF(ISNUMBER(C36),$C$27-$C36,"") -> 11124.5 | E36: =IF(ISNUMBER(C36),C36-C35,"") -> 500 | G36: 269
A37: =IF($G$33 > ROW()-ROW($A$31),CONCATENATE("FBG",ROW()-ROW($A$30)),"") -> FBG7 | B37: =IF(Definitions!$W$2,IF($G$33 > ROW()-ROW($A$31),$B36+$G$41,""),"") -> 1541.9 | C37: =IF(AND($G$33 > ROW()-ROW($A$31),Definitions!$Y$2),$C36+$G$48,"") -> 3062 | D37: =IF(ISNUMBER(C37),$C$27-$C37,"") -> 10624.5 | E37: =IF(ISNUMBER(C37),C37-C36,"") -> 500
A38: =IF($G$33 > ROW()-ROW($A$31),CONCATENATE("FBG",ROW()-ROW($A$30)),"") -> FBG8 | B38: =IF(Definitions!$W$2,IF($G$33 > ROW()-ROW($A$31),$B37+$G$41,""),"") -> 1543.05 | C38: =IF(AND($G$33 > ROW()-ROW($A$31),Definitions!$Y$2),$C37+$G$48,"") -> 3562 | D38: =IF(ISNUMBER(C38),$C$27-$C38,"") -> 10124.5 | E38: =IF(ISNUMBER(C38),C38-C37,"") -> 500 | G38: FBG Wavelength (nm)
A39: =IF($G$33 > ROW()-ROW($A$31),CONCATENATE("FBG",ROW()-ROW($A$30)),"") -> FBG9 | B39: =IF(Definitions!$W$2,IF($G$33 > ROW()-ROW($A$31),$B38+$G$41,""),"") -> 1544.2 | C39: =IF(AND($G$33 > ROW()-ROW($A$31),Definitions!$Y$2),$C38+$G$48,"") -> 4062 | D39: =IF(ISNUMBER(C39),$C$27-$C39,"") -> 9624.5 | E39: =IF(ISNUMBER(C39),C39-C38,"") -> 500 | G39: Equal Wavelength Spacing
A40: =IF($G$33 > ROW()-ROW($A$31),CONCATENATE("FBG",ROW()-ROW($A$30)),"") -> FBG10 | B40: =IF(Definitions!$W$2,IF($G$33 > ROW()-ROW($A$31),$B39+$G$41,""),"") -> 1545.35 | C40: =IF(AND($G$33 > ROW()-ROW($A$31),Definitions!$Y$2),$C39+$G$48,"") -> 4562 | D40: =IF(ISNUMBER(C40),$C$27-$C40,"") -> 9124.5 | E40: =IF(ISNUMBER(C40),C40-C39,"") -> 500 | G40: Wavelength Spacing (nm)
A41: =IF($G$33 > ROW()-ROW($A$31),CONCATENATE("FBG",ROW()-ROW($A$30)),"") -> FBG11 | B41: =IF(Definitions!$W$2,IF($G$33 > ROW()-ROW($A$31),$B40+$G$41,""),"") -> 1546.5 | C41: =IF(AND($G$33 > ROW()-ROW($A$31),Definitions!$Y$2),$C40+$G$48,"") -> 5062 | D41: =IF(ISNUMBER(C41),$C$27-$C41,"") -> 8624.5 | E41: =IF(ISNUMBER(C41),C41-C40,"") -> 500 | G41: 1.15
A42: =IF($G$33 > ROW()-ROW($A$31),CONCATENATE("FBG",ROW()-ROW($A$30)),"") -> FBG12 | B42: =IF(Definitions!$W$2,IF($G$33 > ROW()-ROW($A$31),$B41+$G$41,""),"") -> 1547.65 | C42: =IF(AND($G$33 > ROW()-ROW($A$31),Definitions!$Y$2),$C41+$G$48,"") -> 5562 | D42: =IF(ISNUMBER(C42),$C$27-$C42,"") -> 8124.5 | E42: =IF(ISNUMBER(C42),C42-C41,"") -> 500 | G42: Wavelength first FBG
A43: =IF($G$33 > ROW()-ROW($A$31),CONCATENATE("FBG",ROW()-ROW($A$30)),"") -> FBG13 | B43: =IF(Definitions!$W$2,IF($G$33 > ROW()-ROW($A$31),$B42+$G$41,""),"") -> 1548.8 | C43: =IF(AND($G$33 > ROW()-ROW($A$31),Definitions!$Y$2),$C42+$G$48,"") -> 6062 | D43: =IF(ISNUMBER(C43),$C$27-$C43,"") -> 7624.5 | E43: =IF(ISNUMBER(C43),C43-C42,"") -> 500 | G43: 1535
A44: =IF($G$33 > ROW()-ROW($A$31),CONCATENATE("FBG",ROW()-ROW($A$30)),"") -> FBG14 | B44: =IF(Definitions!$W$2,IF($G$33 > ROW()-ROW($A$31),$B43+$G$41,""),"") -> 1549.95 | C44: =IF(AND($G$33 > ROW()-ROW($A$31),Definitions!$Y$2),$C43+$G$48,"") -> 6562 | D44: =IF(ISNUMBER(C44),$C$27-$C44,"") -> 7124.5 | E44: =IF(ISNUMBER(C44),C44-C43,"") -> 500
A45: =IF($G$33 > ROW()-ROW($A$31),CONCATENATE("FBG",ROW()-ROW($A$30)),"") -> FBG15 | B45: =IF(Definitions!$W$2,IF($G$33 > ROW()-ROW($A$31),$B44+$G$41,""),"") -> 1551.1 | C45: =IF(AND($G$33 > ROW()-ROW($A$31),Definitions!$Y$2),$C44+$G$48,"") -> 7062 | D45: =IF(ISNUMBER(C45),$C$27-$C45,"") -> 6624.5 | E45: =IF(ISNUMBER(C45),C45-C44,"") -> 500 | G45: FBG Spacing (mm)
A46: =IF($G$33 > ROW()-ROW($A$31),CONCATENATE("FBG",ROW()-ROW($A$30)),"") -> FBG16 | B46: =IF(Definitions!$W$2,IF($G$33 > ROW()-ROW($A$31),$B45+$G$41,""),"") -> 1552.25 | C46: =IF(AND($G$33 > ROW()-ROW($A$31),Definitions!$Y$2),$C45+$G$48,"") -> 7562 | D46: =IF(ISNUMBER(C46),$C$27-$C46,"") -> 6124.5 | E46: =IF(ISNUMBER(C46),C46-C45,"") -> 500 | G46: Equal FBG Spacing
A47: =IF($G$33 > ROW()-ROW($A$31),CONCATENATE("FBG",ROW()-ROW($A$30)),"") -> FBG17 | B47: =IF(Definitions!$W$2,IF($G$33 > ROW()-ROW($A$31),$B46+$G$41,""),"") -> 1553.4 | C47: =IF(AND($G$33 > ROW()-ROW($A$31),Definitions!$Y$2),$C46+$G$48,"") -> 8062 | D47: =IF(ISNUMBER(C47),$C$27-$C47,"") -> 5624.5 | E47: =IF(ISNUMBER(C47),C47-C46,"") -> 500 | G47: Spacing (mm)
A48: =IF($G$33 > ROW()-ROW($A$31),CONCATENATE("FBG",ROW()-ROW($A$30)),"") -> FBG18 | B48: =IF(Definitions!$W$2,IF($G$33 > ROW()-ROW($A$31),$B47+$G$41,""),"") -> 1554.55 | C48: =IF(AND($G$33 > ROW()-ROW($A$31),Definitions!$Y$2),$C47+$G$48,"") -> 8562 | D48: =IF(ISNUMBER(C48),$C$27-$C48,"") -> 5124.5 | E48: =IF(ISNUMBER(C48),C48-C47,"") -> 500 | G48: 500
A49: =IF($G$33 > ROW()-ROW($A$31),CONCATENATE("FBG",ROW()-ROW($A$30)),"") -> FBG19 | B49: =IF(Definitions!$W$2,IF($G$33 > ROW()-ROW($A$31),$B48+$G$41,""),"") -> 1555.7 | C49: =IF(AND($G$33 > ROW()-ROW($A$31),Definitions!$Y$2),$C48+$G$48,"") -> 9062 | D49: =IF(ISNUMBER(C49),$C$27-$C49,"") -> 4624.5 | E49: =IF(ISNUMBER(C49),C49-C48,"") -> 500
A50: =IF($G$33 > ROW()-ROW($A$31),CONCATENATE("FBG",ROW()-ROW($A$30)),"") -> FBG20 | B50: =IF(Definitions!$W$2,IF($G$33 > ROW()-ROW($A$31),$B49+$G$41,""),"") -> 1556.85 | C50: =IF(AND($G$33 > ROW()-ROW($A$31),Definitions!$Y$2),$C49+$G$48,"") -> 9562 | D50: =IF(ISNUMBER(C50),$C$27-$C50,"") -> 4124.5 | E50: =IF(ISNUMBER(C50),C50-C49,"") -> 500
...

Sheet Definitions
A1: Contact | C1: Fiber Type | D1: Core Type | E1: Mode Field | F1: Fiber Cladding | G1: Coating | H1: Manufacturer | I1: ITU-T | K1: Provided | M1: FemtoPlus | O1: Apodized | Q1: Spectrum | S1: FBG | U1: Fiber | W1: WL spacing | Y1: Pos spacing | AA1: Label | AC1: Simpl. Packag.
A2: Friedrich | C2: SMF-28 Ultra | D2: Single Mode | E2: 10.4 | F2: 125 | G2: Acrylate | H2: Corning | I2: G.657.A1 | K2: eFG | M2: yes | O2: yes | Q2: linear | S2: black, FBG-length (±1mm tolerance) | U2: black | W2: TRUE | Y2: TRUE | AA2: on spool | AC2: yes
A3: Gillooly | C3: SMF-28 Ultra 200 | D3: Single Mode | E3: 10.4 | F3: 125 | G3: Acrylate | H3: Corning | I3: G.657.A1 | K3: customer | M3: no | O3: no | Q3: logarithmic | S3: no | U3: black, 3 cm dots | AA3: on fiber | AC3: no
A4: Gong | C4: SM1330-E9/125PI | D4: Single Mode | E4: 10,4 | F4: 125 | G4: Polyimide | H4: J-Fiber | I4: - | S4: black, plus black 25 mm to sides | U4: green
A5: Kampling | C5: SM1500SC(7/80)P | D5: Pure Core | E5: 6,7 - 7,6 | F5: 80 | G5: Polyimide | H5: Fibercore | I5: - | S5: black 12,5 mm to sides | U5: no
A6: Reif | C6: SM1250BI(9.8/125)P | D6: Bend Insensitive | E6: 9 - 10,6 | F6: 125 | G6: Polyimide | H6: Fibercore | I6: - | S6: red | U6: Other (see Remarks)
A7: Vasileiou | C7: SM1250SC(9/125) | D7: Pure Core | E7: 8,3 - 9,6 | F7: 125 | G7: Acrylate | H7: Fibercore | I7: - | S7: Other (see Remarks)
A8: Vouilleme | C8: SM1250SC(9/125)P | D8: Pure Core | E8: 8,3 - 9,6 | F8: 125 | G8: Polyimide | H8: Fibercore | I8: -
A9: Yang | C9: SM1250SC(10/125)P | D9: Pure Core | E9: 9,2 - 10,8 | F9: 125 | G9: Polyimide | H9: Fibercore | I9: -
A10: Hoffmann | C10: IXF-RAD-SM-1550-014-PI | D10: Radiation Hard | E10: 8 - 10 | F10: 125 | G10: Polyimide | H10: iXblue | I10: -
C11: SMF-60-MTDA-125-1 | D11: Pure Core | E11: 9,3 - 10,7 | F11: 125 | G11: Acrylate | H11: Verrillon | I11: -
C12: Ormocer | D12: Single Mode | E12: - | F12: 125 | G12: Ormocer | H12: J-Fiber | I12: -
C13: Single Mode Acrylate | D13: Single Mode | E13: - | F13: - | G13: Acrylate | H13: - | I13: -
C14: Single Mode PI | D14: Single Mode | E14: - | F14: - | G14: Polyimide | H14: - | I14: -
C15: Pure Core PI | D15: Pure Core | E15: - | F15: - | G15: Polyimide | H15: - | I15: -
C16: Other (see Remarks) | D16: - | E16: - | F16: - | G16: - | H16: - | I16: -
